Workbook

Sheet Sales forecasts
C3: Historical | F3: Planned | R3: Futur
C4: Oct. | D4: Nov. | E4: Dec. | F4: Jan. | G4: Feb. | H4: Mar | I4: Apr. | J4: May | K4: Jun. | L4: Jul. | M4: Aug | N4: Sep. | O4: Oct. | P4: Nov. | Q4: Dec. | R4: Jan.
B5: i | C5: 1 | D5: 2 | E5: 3 | F5: 4 | G5: 5 | H5: 6 | I5: 7 | J5: 8 | K5: 9 | L5: 10 | M5: 11 | N5: 12 | O5: 13 | P5: 14 | Q5: 15
B6: xi | C6: -3 | D6: -2 | E6: -1 | F6: 1 | G6: 2 | H6: 3 | I6: 4 | J6: 5 | K6: 6 | L6: 7 | M6: 8 | N6: 9 | O6: 10 | P6: 11 | Q6: 12
A7: Sales / Demand
A8: Sales forecasts | B8: k€ | C8: ='S&OP'!C17 -> 9990 | D8: ='S&OP'!D17 -> 13110 | E8: ='S&OP'!E17 -> 6900 | F8: ='S&OP'!F17 -> 7590 | G8: ='S&OP'!G17 -> 8400 | H8: ='S&OP'!H17 -> 10200 | I8: ='S&OP'!I17 -> 9000 | J8: ='S&OP'!J17 -> 11790 | ... R8: ='S&OP'!R17 -> 8010
B9: 1000 units | C9: 333 | D9: 437 | E9: 230 | F9: 253 | G9: 280 | H9: 340 | I9: 300 | J9: 393 | K9: 233 | L9: 287 | M9: 420 | N9: 480 | O9: 427 | P9: 527 | Q9: 393 | R9: 267
A11: Cumulative sales forecasts | B11: 1000 units | E11: 0 | F11: =SUM($F9:F9) -> 253 | G11: =SUM($F9:G9) -> 533 | H11: =SUM($F9:H9) -> 873 | I11: =SUM($F9:I9) -> 1173 | J11: =SUM($F9:J9) -> 1566 | K11: =SUM($F9:K9) -> 1799 | L11: =SUM($F9:L9) -> 2086 | M11: =SUM($F9:M9) -> 2506 | ... Q11: =SUM($F9:Q9) -> 4333
A12: Cumulative smoothed production | B12: 1000 units | E12: 0 | F12: =SUM(F9:Q9)/12 -> 361.08333 | G12: =$F12+F12 -> 722.16667 | H12: =$F12+G12 -> 1083.25 | I12: =$F12+H12 -> 1444.3333 | J12: =$F12+I12 -> 1805.4167 | K12: =$F12+J12 -> 2166.5 | L12: =$F12+K12 -> 2527.5833 | M12: =$F12+L12 -> 2888.6667 | N12: =$F12+M12 -> 3249.75 | ... Q12: =$F12+P12 -> 4333

Sheet S&OP
T1: Cost in k€ | U1: Chase Strategy - Plan à stock constant | V1: Chase Strategy - Plan à couverture de stock constante | W1: Level Strategy - Plan à production constante | X1: Mixed Operating Strategy
A2: Average value of one unit produced | B2: € | C2: 30 | F2: xxx | G2: Entered parameters | T2: Recruit. | U2: =R45 -> 928.91917 | V2: =R92 -> 669.58574 | W2: =R144 -> 143.12984 | X2: =R193 -> 283.6039
A3: Employee productivity factor | B3: Unit /Emp. J | C3: 8 | F3: xxx | G3: Calculated parameters but can also be overridden | T3: Termin. | U3: =R46 -> 1812.6729 | V3: =R93 -> 1262.7768 | W3: =R145 -> 0 | X3: =R194 -> 5.6347403
A4: Initial inventory (end of Sept.) | C4: 0 | T4: Inventory | U4: =R47 -> 1548 | V4: =R94 -> 663.87134 | W4: =R146 -> 2721.084 | X4: =R195 -> 896.4
A5: Inventory holding rate | C5: 0.02 | T5: Total | U5: =R48 -> 4289.5921 | V5: =R95 -> 2596.2339 | W5: =R147 -> 2864.2138 | X5: =R196 -> 1185.6386
A6: Hiring / recruitment cost | B6: k€ | C6: 0.2
A7: Termination / layoff cost | B7: k€ | C7: 0.5
A8: Initial workforce | C8: 1437
A10: S&OP Chase Strategy - Plan à stock constant
C12: Historical | F12: Planned | R12: Futur
C13: Oct. | D13: Nov. | E13: Dec. | F13: Jan. | G13: Feb. | H13: Mar | I13: Apr. | J13: May | K13: Jun. | L13: Jul. | M13: Aug | N13: Sep. | O13: Oct. | P13: Nov. | Q13: Dec. | R13: Jan.
B14: i | C14: 1 | D14: 2 | E14: 3 | F14: 4 | G14: 5 | H14: 6 | I14: 7 | J14: 8 | K14: 9 | L14: 10 | M14: 11 | N14: 12 | O14: 13 | P14: 14 | Q14: 15
B15: xi | C15: -3 | D15: -2 | E15: -1 | F15: 1 | G15: 2 | H15: 3 | I15: 4 | J15: 5 | K15: 6 | L15: 7 | M15: 8 | N15: 9 | O15: 10 | P15: 11 | Q15: 12
A16: Sales / Demand
A17: Sales forecasts | B17: k€ | C17: =ROUND(C18*$C$2,1) -> 9990 | D17: =ROUND(D18*$C$2,1) -> 13110 | E17: =ROUND(E18*$C$2,1) -> 6900 | F17: =ROUND(F18*$C$2,1) -> 7590 | G17: =ROUND(G18*$C$2,1) -> 8400 | H17: =ROUND(H18*$C$2,1) -> 10200 | I17: =ROUND(I18*$C$2,1) -> 9000 | J17: =ROUND(J18*$C$2,1) -> 11790 | ... R17: =ROUND(R18*$C$2,1) -> 8010
B18: 1000 units | C18: 333 | D18: 437 | E18: 230 | F18: 253 | G18: 280 | H18: 340 | I18: 300 | J18: 393 | K18: 233 | L18: 287 | M18: 420 | N18: 480 | O18: 427 | P18: 527 | Q18: 393 | R18: 267
A19: Actual sales | B19: 1000 units | C19: 300 | D19: 400 | E19: 200
A20: Difference | B20: 1000 units | C20: =C19-C18 -> -33 | D20: =D19-D18 -> -37 | E20: =E19-E18 -> -30
A21: Cumulative difference | B21: 1000 units | C21: =C20 -> -33 | D21: =SUM($C20:D20) -> -70 | E21: =SUM($C20:E20) -> -100
A23: Production
A24: Planned production – Production plan | B24: 1000 units | C24: =C18 -> 333 | D24: =D18 -> 437 | E24: =E18 -> 230 | F24: =F18 -> 253 | G24: =G18 -> 280 | H24: =H18 -> 340 | I24: =I18 -> 300 | J24: =J18 -> 393 | ... Q24: =Q18 -> 393
A25: Planned resource requirements | B25: Employees | C25: =C24*1000/C26/$C$3 -> 1892.0455 | D25: =D24*1000/D26/$C$3 -> 2731.25 | E25: =E24*1000/E26/$C$3 -> 1437.5 | F25: =F24*1000/($C$3*F26) -> 1581.25 | G25: =G24*1000/($C$3*G26) -> 1666.6667 | H25: =H24*1000/($C$3*H26) -> 1847.8261 | I25: =I24*1000/($C$3*I26) -> 1875 | J25: =J24*1000/($C$3*J26) -> 2232.9545 | K25: =K24*1000/($C$3*K26) -> 1323.8636 | L25: =L24*1000/($C$3*L26) -> 3587.5 | M25: =M24*1000/($C$3*M26) -> 2282.6087 | ... Q25: =Q24*1000/($C$3*Q26) -> 2456.25
A26: Number of working days | B26: Working days. | C26: 22 | D26: 20 | E26: 20 | F26: 20 | G26: 21 | H26: 23 | I26: 20 | J26: 22 | K26: 22 | L26: 10 | M26: 23 | N26: 20 | O26: 22 | P26: 20 | Q26: 20 | R26: 20
A27: Actual production | B27: 1000 units | C27: 360 | D27: 455 | E27: 300
A28: Difference | B28: 1000 units | C28: =C27-C24 -> 27 | D28: =D27-D24 -> 18 | E28: =E27-E24 -> 70
A29: Cumulative difference | B29: 1000 units | C29: =C28 -> 27 | D29: =SUM($C28:D28) -> 45 | E29: =SUM($C28:E28) -> 115
A31: End-of-month inventory
A32: Planned | B32: 1000 units | C32: =C4+C24-C18 -> 0 | D32: =C32+D24-D18 -> 0 | E32: =D32+E24-E18 -> 0 | F32: =E34+F24-F18 -> 215 | G32: =F32+G24-G18 -> 215 | H32: =G32+H24-H18 -> 215 | I32: =H32+I24-I18 -> 215 | J32: =I32+J24-J18 -> 215 | K32: =J32+K24-K18 -> 215 | L32: =K32+L24-L18 -> 215 | M32: =L32+M24-M18 -> 215 | N32: =M32+N24-N18 -> 215 | ... Q32: =P32+Q24-Q18 -> 215
B33: € | C33: =C32*$C$2 -> 0 | D33: =D32*$C$2 -> 0 | E33: =E32*$C$2 -> 0 | F33: =F32*$C$2 -> 6450 | G33: =G32*$C$2 -> 6450 | H33: =H32*$C$2 -> 6450 | I33: =I32*$C$2 -> 6450 | J33: =J32*$C$2 -> 6450 | ... Q33: =Q32*$C$2 -> 6450
A34: Actual | B34: 1000 units | C34: =C4+C27-C19 -> 60 | D34: =C34+D27-D19 -> 115 | E34: =D34+E27-E19 -> 215
A35: Stock coverage / Days of supply | B35: days | C35: =C34/(D19/D26) -> 3 | D35: =D34/(E19/E26) -> 11.5 | E35: =E34/(F18/F26) -> 16.996047 | F35: =F32/(G18/G26) -> 16.125 | G35: =G32/(H18/H26) -> 14.544118 | H35: =H32/(I18/I26) -> 14.333333 | I35: =I32/(J18/J26) -> 12.035623 | J35: =J32/(K18/K26) -> 20.300429 | K35: =K32/(L18/L26) -> 7.4912892 | L35: =L32/(M18/M26) -> 11.77381 | M35: =M32/(N18/N26) -> 8.9583333 | ... Q35: =Q32/(R18/R26) -> 16.104869
A36: Service level | C36: 98 | D36: 100 | E36: 100
E40: Recruit. | F40: =MAX(F25-$C$8,0) -> 144.25 | G40: =MAX(G25-F42,0) -> 85.416667 | H40: =MAX(H25-G42,0) -> 181.15942 | I40: =MAX(I25-H42,0) -> 27.173913 | J40: =MAX(J25-I42,0) -> 357.95455 | K40: =MAX(K25-J42,0) -> 0 | L40: =MAX(L25-K42,0) -> 2263.6364 | M40: =MAX(M25-L42,0) -> 0 | N40: =MAX(N25-M42,0) -> 717.3913 | ... Q40: =MAX(Q25-P42,0) -> 0
E41: Termin. | F41: =MAX($C$8-F25,0) -> 0 | G41: =MAX(F42-G25,0) -> 0 | H41: =MAX(G42-H25,0) -> 0 | I41: =MAX(H42-I25,0) -> 0 | J41: =MAX(I42-J25,0) -> 0 | K41: =MAX(J42-K25,0) -> 909.09091 | L41: =MAX(K42-L25,0) -> 0 | M41: =MAX(L42-M25,0) -> 1304.8913 | N41: =MAX(M42-N25,0) -> 0 | ... Q41: =MAX(P42-Q25,0) -> 837.5
E42: Workforce | F42: =$C$8+F40-F41 -> 1581.25 | G42: =F42+G40-G41 -> 1666.6667 | H42: =G42+H40-H41 -> 1847.8261 | I42: =H42+I40-I41 -> 1875 | J42: =I42+J40-J41 -> 2232.9545 | K42: =J42+K40-K41 -> 1323.8636 | L42: =K42+L40-L41 -> 3587.5 | M42: =L42+M40-M41 -> 2282.6087 | N42: =M42+N40-N41 -> 3000 | ... Q42: =P42+Q40-Q41 -> 2456.25
E44: Cost in k€ | R44: Totals
E45: Recruit. | F45: =F40*$C$6 -> 28.85 | G45: =G40*$C$6 -> 17.083333 | H45: =H40*$C$6 -> 36.231884 | I45: =I40*$C$6 -> 5.4347826 | J45: =J40*$C$6 -> 71.590909 | K45: =K40*$C$6 -> 0 | L45: =L40*$C$6 -> 452.72727 | M45: =M40*$C$6 -> 0 | ... Q45: =Q40*$C$6 -> 0 | R45: =SUM(F45:Q45) -> 928.91917
E46: Termin. | F46: =F41*$C$7 -> 0 | G46: =G41*$C$7 -> 0 | H46: =H41*$C$7 -> 0 | I46: =I41*$C$7 -> 0 | J46: =J41*$C$7 -> 0 | K46: =K41*$C$7 -> 454.54545 | L46: =L41*$C$7 -> 0 | M46: =M41*$C$7 -> 652.44565 | ... Q46: =Q41*$C$7 -> 418.75 | R46: =SUM(F46:Q46) -> 1812.6729
E47: Stocks | F47: =F32*$C$2*$C$5 -> 129 | G47: =G32*$C$2*$C$5 -> 129 | H47: =H32*$C$2*$C$5 -> 129 | I47: =I32*$C$2*$C$5 -> 129 | J47: =J32*$C$2*$C$5 -> 129 | K47: =K32*$C$2*$C$5 -> 129 | L47: =L32*$C$2*$C$5 -> 129 | M47: =M32*$C$2*$C$5 -> 129 | ... Q47: =Q32*$C$2*$C$5 -> 129 | R47: =SUM(F47:Q47) -> 1548
Q48: Total Cost : | R48: =SUM(R45:R47) -> 4289.5921
...
